Workbook

Sheet Discovery
L2: QLIK SENSE DISCOVERY · WHAT THE APPS CONTAIN
A5: Input: /home/joginder-singh/workspace/qliksense_to_powerbi_premigration/sample_files · generated 2026-10-08 21:41
A7: NAVIGATE | H7: ='Totals'!$B$9 | Q7: ='Totals'!$B$20 | Z7: ='Totals'!$B$21 | AI7: ='Totals'!$B$22 | AR7: SCAN SUMMARY
A8: =HYPERLINK("#'Discovery'!A1","Discovery") | AR8: Input folder | BB8: sample_files
A9: =HYPERLINK("#'Apps'!A1","Apps") | H9: APPS DISCOVERED | Q9: SHEETS | Z9: VISUALIZATIONS ON SHEETS | AI9: VISUALIZATION TYPES USED | AR9: Sub-folders included | BB9: No
A10: =HYPERLINK("#'Sheets'!A1","Sheets") | AR10: Output folder | BB10: output
A11: =HYPERLINK("#'Visualizations'!A1","Visualizations") | AR11: Apps discovered | BB11: ='Totals'!$B$9
A12: =HYPERLINK("#'MasterMeasures'!A1","Master Measures") | H12: ='Totals'!$B$30 | Q12: ='Totals'!$B$35 | Z12: ='Totals'!$B$37 | AI12: ='Totals'!$B$38 | AR12: Apps parsed | BB12: ='Totals'!$B$10
A13: =HYPERLINK("#'MasterDimensions'!A1","Master Dimensions") | AR13: Apps failed | BB13: ='Totals'!$B$11
A14: =HYPERLINK("#'MasterVisualizations'!A1","Master Visuals") | H14: MASTER MEASURES | Q14: MASTER DIMENSIONS | Z14: MASTER VISUALIZATIONS | AI14: VARIABLES | AR14: Total size (MB) | BB14: ='Totals'!$B$12
A15: =HYPERLINK("#'MasterItemUsage'!A1","Master Item Usage") | AR15: Low-complexity apps | BB15: ='Totals'!$B$15
A16: =HYPERLINK("#'Variables'!A1","Variables") | AR16: Medium-complexity apps | BB16: ='Totals'!$B$14
A17: =HYPERLINK("#'Bookmarks'!A1","Bookmarks") | H17: ='Totals'!$B$43 | Q17: ='Totals'!$B$45 | Z17: ='Totals'!$B$47 | AI17: ='Totals'!$B$49 | AR17: High-complexity apps | BB17: ='Totals'!$B$13
A18: =HYPERLINK("#'Stories'!A1","Stories") | AR18: Portfolio effort score | BB18: ='Totals'!$B$16
A19: =HYPERLINK("#'LoadScript'!A1","Load Script") | H19: LOAD SCRIPT TABS | Q19: LOAD STATEMENTS | Z19: DISTINCT EXTERNAL SOURCES | AI19: DATA ROWS STORED | AR19: Bookmarks | BB19: ='Totals'!$B$24
A20: =HYPERLINK("#'DataSources'!A1","Data Sources") | AR20: Stories | BB20: ='Totals'!$B$25
A21: =HYPERLINK("#'DataTables'!A1","Data Tables") | AR21: Legacy QlikView objects | BB21: ='Totals'!$B$51
A22: =HYPERLINK("#'Fields'!A1","Fields") | H22: ='Totals'!$B$13 | Q22: ='Totals'!$B$33 | Z22: ='Totals'!$B$34 | AI22: ='Totals'!$B$56 | AR22: Discovered by | BB22: qvf-app + Kanerika discovery
A23: =HYPERLINK("#'LegacyObjects'!A1","Legacy Objects") | AR23: Generated | BB23: 2026-10-08 21:41
A24: =HYPERLINK("#'ExpressionFunctions'!A1","Functions") | H24: HIGH-COMPLEXITY APPS | Q24: HIGH-COMPLEXITY MEASURES | Z24: UNUSED MASTER MEASURES | AI24: PARSER WARNINGS
A25: =HYPERLINK("#'Media'!A1","Media")
A26: =HYPERLINK("#'StoredObjects'!A1","Stored Objects")
A27: =HYPERLINK("#'Warnings'!A1","Warnings")
A28: =HYPERLINK("#'Information'!A1","Information") | H28: AT A GLANCE
A29: =HYPERLINK("#'Totals'!A1","Totals")

Sheet Apps
C2: Apps · one row per Qlik app
A5: =HYPERLINK("#'Discovery'!A1","« Back to Discovery") | B5: One row per app: file, status, every count, effort score and migration complexity (all formulas).
A6: App | B6: App title | C6: File | D6: Size (MB) | E6: Status | F6: Qlik version | G6: Last reload | H6: Data stored | I6: Sheets | J6: Visualizations | K6: Master measures | L6: Set analysis | M6: Aggr() | N6: High-complexity measures | O6: Master dimensions | P6: Drill-down | Q6: Master visualizations | R6: Variables | S6: Expression variables | T6: Bookmarks | U6: Stories | V6: Script tabs | W6: LOAD statements | X6: Distinct external sources | Y6: Data tables | Z6: Data rows | AA6: Fields | AB6: Legacy objects | AC6: Warnings | AD6: Effort score | AE6: Complexity
A7: Executive Dashboard | B7: Executive Dashboard | C7: Executive Dashboard.qvf | D7: 2.75 | E7: Parsed | F7: 2.1.1 | G7: 2014-06-27 15:51:29 | H7: Yes | I7: =COUNTIF('Sheets'!$A$7:$A$100000,$A7) | J7: =COUNTIF('Visualizations'!$A$7:$A$100000,$A7) | K7: =COUNTIF('MasterMeasures'!$A$7:$A$100000,$A7) | L7: =COUNTIFS('MasterMeasures'!$A$7:$A$100000,$A7,'MasterMeasures'!$G$7:$G$100000,"Yes") | M7: =COUNTIFS('MasterMeasures'!$A$7:$A$100000,$A7,'MasterMeasures'!$H$7:$H$100000,"Yes") | N7: =COUNTIFS('MasterMeasures'!$A$7:$A$100000,$A7,'MasterMeasures'!$K$7:$K$100000,"High") | O7: =COUNTIF('MasterDimensions'!$A$7:$A$100000,$A7) | P7: =COUNTIFS('MasterDimensions'!$A$7:$A$100000,$A7,'MasterDimensions'!$E$7:$E$100000,"Drill-down") | Q7: =COUNTIF('MasterVisualizations'!$A$7:$A$100000,$A7) | R7: =COUNTIF('Variables'!$A$7:$A$100000,$A7) | S7: =COUNTIFS('Variables'!$A$7:$A$100000,$A7,'Variables'!$F$7:$F$100000,"Yes") | T7: =COUNTIF('Bookmarks'!$A$7:$A$100000,$A7) | U7: =COUNTIF('Stories'!$A$7:$A$100000,$A7) | V7: =COUNTIF('LoadScript'!$A$7:$A$100000,$A7) | W7: =SUMIF('LoadScript'!$A$7:$A$100000,$A7,'LoadScript'!$E$7:$E$100000) | X7: =SUMIF('DataSources'!$A$7:$A$100000,$A7,'DataSources'!$F$7:$F$100000) | Y7: =COUNTIF('DataTables'!$A$7:$A$100000,$A7) | Z7: =SUMIF('DataTables'!$A$7:$A$100000,$A7,'DataTables'!$D$7:$D$100000) | AA7: =COUNTIF('Fields'!$A$7:$A$100000,$A7) | AB7: =COUNTIF('LegacyObjects'!$A$7:$A$100000,$A7) | AC7: =COUNTIF('Warnings'!$A$7:$A$100000,$A7) | AD7: =IF($E7="Parsed",I7*'Totals'!$C$77+J7*'Totals'!$C$78+K7*'Totals'!$C$79+L7*'Totals'!$C$80+M7*'Totals'!$C$81+O7*'Totals'!$C$82+P7*'Totals'!$C$83+Q7*'Totals'!$C$84+S7*'Totals'!$C$85+V7*'Totals'!$C$86+W7*'Totals'!$C$87+X7*'Totals'!$C$88+AB7*'Totals'!$C$89+T7*'Totals'!$C$90+U7*'Totals'!$C$91,0) | AE7: =IF($E7<>"Parsed","-",IF(AD7>='Totals'!$C$94,"High",IF(AD7>='Totals'!$C$93,"Medium","Low")))
A8: First Qlikview Report | B8: First Qlikview Report | C8: First Qlikview Report.qvf | D8: 0.21 | E8: Parsed | F8: 12.70.20000 | G8: 2026-09-24 14:00:48 | H8: Yes | I8: =COUNTIF('Sheets'!$A$7:$A$100000,$A8) | J8: =COUNTIF('Visualizations'!$A$7:$A$100000,$A8) | K8: =COUNTIF('MasterMeasures'!$A$7:$A$100000,$A8) | L8: =COUNTIFS('MasterMeasures'!$A$7:$A$100000,$A8,'MasterMeasures'!$G$7:$G$100000,"Yes") | M8: =COUNTIFS('MasterMeasures'!$A$7:$A$100000,$A8,'MasterMeasures'!$H$7:$H$100000,"Yes") | N8: =COUNTIFS('MasterMeasures'!$A$7:$A$100000,$A8,'MasterMeasures'!$K$7:$K$100000,"High") | O8: =COUNTIF('MasterDimensions'!$A$7:$A$100000,$A8) | P8: =COUNTIFS('MasterDimensions'!$A$7:$A$100000,$A8,'MasterDimensions'!$E$7:$E$100000,"Drill-down") | Q8: =COUNTIF('MasterVisualizations'!$A$7:$A$100000,$A8) | R8: =COUNTIF('Variables'!$A$7:$A$100000,$A8) | S8: =COUNTIFS('Variables'!$A$7:$A$100000,$A8,'Variables'!$F$7:$F$100000,"Yes") | T8: =COUNTIF('Bookmarks'!$A$7:$A$100000,$A8) | U8: =COUNTIF('Stories'!$A$7:$A$100000,$A8) | V8: =COUNTIF('LoadScript'!$A$7:$A$100000,$A8) | W8: =SUMIF('LoadScript'!$A$7:$A$100000,$A8,'LoadScript'!$E$7:$E$100000) | X8: =SUMIF('DataSources'!$A$7:$A$100000,$A8,'DataSources'!$F$7:$F$100000) | Y8: =COUNTIF('DataTables'!$A$7:$A$100000,$A8) | Z8: =SUMIF('DataTables'!$A$7:$A$100000,$A8,'DataTables'!$D$7:$D$100000) | AA8: =COUNTIF('Fields'!$A$7:$A$100000,$A8) | AB8: =COUNTIF('LegacyObjects'!$A$7:$A$100000,$A8) | AC8: =COUNTIF('Warnings'!$A$7:$A$100000,$A8) | AD8: =IF($E8="Parsed",I8*'Totals'!$C$77+J8*'Totals'!$C$78+K8*'Totals'!$C$79+L8*'Totals'!$C$80+M8*'Totals'!$C$81+O8*'Totals'!$C$82+P8*'Totals'!$C$83+Q8*'Totals'!$C$84+S8*'Totals'!$C$85+V8*'Totals'!$C$86+W8*'Totals'!$C$87+X8*'Totals'!$C$88+AB8*'Totals'!$C$89+T8*'Totals'!$C$90+U8*'Totals'!$C$91,0) | AE8: =IF($E8<>"Parsed","-",IF(AD8>='Totals'!$C$94,"High",IF(AD8>='Totals'!$C$93,"Medium","Low")))
A9: Helpdesk Management | B9: Helpdesk Management | C9: Helpdesk Management.qvf | D9: 1.88 | E9: Parsed | F9: 2.1.1 | G9: 1753-01-01 00:00:00 | H9: Yes | I9: =COUNTIF('Sheets'!$A$7:$A$100000,$A9) | J9: =COUNTIF('Visualizations'!$A$7:$A$100000,$A9) | K9: =COUNTIF('MasterMeasures'!$A$7:$A$100000,$A9) | L9: =COUNTIFS('MasterMeasures'!$A$7:$A$100000,$A9,'MasterMeasures'!$G$7:$G$100000,"Yes") | M9: =COUNTIFS('MasterMeasures'!$A$7:$A$100000,$A9,'MasterMeasures'!$H$7:$H$100000,"Yes") | N9: =COUNTIFS('MasterMeasures'!$A$7:$A$100000,$A9,'MasterMeasures'!$K$7:$K$100000,"High") | O9: =COUNTIF('MasterDimensions'!$A$7:$A$100000,$A9) | P9: =COUNTIFS('MasterDimensions'!$A$7:$A$100000,$A9,'MasterDimensions'!$E$7:$E$100000,"Drill-down") | Q9: =COUNTIF('MasterVisualizations'!$A$7:$A$100000,$A9) | R9: =COUNTIF('Variables'!$A$7:$A$100000,$A9) | S9: =COUNTIFS('Variables'!$A$7:$A$100000,$A9,'Variables'!$F$7:$F$100000,"Yes") | T9: =COUNTIF('Bookmarks'!$A$7:$A$100000,$A9) | U9: =COUNTIF('Stories'!$A$7:$A$100000,$A9) | V9: =COUNTIF('LoadScript'!$A$7:$A$100000,$A9) | W9: =SUMIF('LoadScript'!$A$7:$A$100000,$A9,'LoadScript'!$E$7:$E$100000) | X9: =SUMIF('DataSources'!$A$7:$A$100000,$A9,'DataSources'!$F$7:$F$100000) | Y9: =COUNTIF('DataTables'!$A$7:$A$100000,$A9) | Z9: =SUMIF('DataTables'!$A$7:$A$100000,$A9,'DataTables'!$D$7:$D$100000) | AA9: =COUNTIF('Fields'!$A$7:$A$100000,$A9) | AB9: =COUNTIF('LegacyObjects'!$A$7:$A$100000,$A9) | AC9: =COUNTIF('Warnings'!$A$7:$A$100000,$A9) | AD9: =IF($E9="Parsed",I9*'Totals'!$C$77+J9*'Totals'!$C$78+K9*'Totals'!$C$79+L9*'Totals'!$C$80+M9*'Totals'!$C$81+O9*'Totals'!$C$82+P9*'Totals'!$C$83+Q9*'Totals'!$C$84+S9*'Totals'!$C$85+V9*'Totals'!$C$86+W9*'Totals'!$C$87+X9*'Totals'!$C$88+AB9*'Totals'!$C$89+T9*'Totals'!$C$90+U9*'Totals'!$C$91,0) | AE9: =IF($E9<>"Parsed","-",IF(AD9>='Totals'!$C$94,"High",IF(AD9>='Totals'!$C$93,"Medium","Low")))
A10: Sales Analysis | B10: Sales Analysis | C10: Sales Analysis.qvf | D10: 0.28 | E10: Parsed | F10: 2.1.1 | G10: 2016-01-24 21:04:00 | H10: Yes | I10: =COUNTIF('Sheets'!$A$7:$A$100000,$A10) | J10: =COUNTIF('Visualizations'!$A$7:$A$100000,$A10) | K10: =COUNTIF('MasterMeasures'!$A$7:$A$100000,$A10) | L10: =COUNTIFS('MasterMeasures'!$A$7:$A$100000,$A10,'MasterMeasures'!$G$7:$G$100000,"Yes") | M10: =COUNTIFS('MasterMeasures'!$A$7:$A$100000,$A10,'MasterMeasures'!$H$7:$H$100000,"Yes") | N10: =COUNTIFS('MasterMeasures'!$A$7:$A$100000,$A10,'MasterMeasures'!$K$7:$K$100000,"High") | O10: =COUNTIF('MasterDimensions'!$A$7:$A$100000,$A10) | P10: =COUNTIFS('MasterDimensions'!$A$7:$A$100000,$A10,'MasterDimensions'!$E$7:$E$100000,"Drill-down") | Q10: =COUNTIF('MasterVisualizations'!$A$7:$A$100000,$A10) | R10: =COUNTIF('Variables'!$A$7:$A$100000,$A10) | S10: =COUNTIFS('Variables'!$A$7:$A$100000,$A10,'Variables'!$F$7:$F$100000,"Yes") | T10: =COUNTIF('Bookmarks'!$A$7:$A$100000,$A10) | U10: =COUNTIF('Stories'!$A$7:$A$100000,$A10) | V10: =COUNTIF('LoadScript'!$A$7:$A$100000,$A10) | W10: =SUMIF('LoadScript'!$A$7:$A$100000,$A10,'LoadScript'!$E$7:$E$100000) | X10: =SUMIF('DataSources'!$A$7:$A$100000,$A10,'DataSources'!$F$7:$F$100000) | Y10: =COUNTIF('DataTables'!$A$7:$A$100000,$A10) | Z10: =SUMIF('DataTables'!$A$7:$A$100000,$A10,'DataTables'!$D$7:$D$100000) | AA10: =COUNTIF('Fields'!$A$7:$A$100000,$A10) | AB10: =COUNTIF('LegacyObjects'!$A$7:$A$100000,$A10) | AC10: =COUNTIF('Warnings'!$A$7:$A$100000,$A10) | AD10: =IF($E10="Parsed",I10*'Totals'!$C$77+J10*'Totals'!$C$78+K10*'Totals'!$C$79+L10*'Totals'!$C$80+M10*'Totals'!$C$81+O10*'Totals'!$C$82+P10*'Totals'!$C$83+Q10*'Totals'!$C$84+S10*'Totals'!$C$85+V10*'Totals'!$C$86+W10*'Totals'!$C$87+X10*'Totals'!$C$88+AB10*'Totals'!$C$89+T10*'Totals'!$C$90+U10*'Totals'!$C$91,0) | AE10: =IF($E10<>"Parsed","-",IF(AD10>='Totals'!$C$94,"High",IF(AD10>='Totals'!$C$93,"Medium","Low")))
A11: TryConfigColorAndAgrField | B11: TryConfigColorAndAgrField | C11: TryConfigColorAndAgrField.qvf | D11: 0.17 | E11: Parsed | F11: 2.1.1 | G11: 2016-03-06 16:53:12 | H11: Yes | I11: =COUNTIF('Sheets'!$A$7:$A$100000,$A11) | J11: =COUNTIF('Visualizations'!$A$7:$A$100000,$A11) | K11: =COUNTIF('MasterMeasures'!$A$7:$A$100000,$A11) | L11: =COUNTIFS('MasterMeasures'!$A$7:$A$100000,$A11,'MasterMeasures'!$G$7:$G$100000,"Yes") | M11: =COUNTIFS('MasterMeasures'!$A$7:$A$100000,$A11,'MasterMeasures'!$H$7:$H$100000,"Yes") | N11: =COUNTIFS('MasterMeasures'!$A$7:$A$100000,$A11,'MasterMeasures'!$K$7:$K$100000,"High") | O11: =COUNTIF('MasterDimensions'!$A$7:$A$100000,$A11) | P11: =COUNTIFS('MasterDimensions'!$A$7:$A$100000,$A11,'MasterDimensions'!$E$7:$E$100000,"Drill-down") | Q11: =COUNTIF('MasterVisualizations'!$A$7:$A$100000,$A11) | R11: =COUNTIF('Variables'!$A$7:$A$100000,$A11) | S11: =COUNTIFS('Variables'!$A$7:$A$100000,$A11,'Variables'!$F$7:$F$100000,"Yes") | T11: =COUNTIF('Bookmarks'!$A$7:$A$100000,$A11) | U11: =COUNTIF('Stories'!$A$7:$A$100000,$A11) | V11: =COUNTIF('LoadScript'!$A$7:$A$100000,$A11) | W11: =SUMIF('LoadScript'!$A$7:$A$100000,$A11,'LoadScript'!$E$7:$E$100000) | X11: =SUMIF('DataSources'!$A$7:$A$100000,$A11,'DataSources'!$F$7:$F$100000) | Y11: =COUNTIF('DataTables'!$A$7:$A$100000,$A11) | Z11: =SUMIF('DataTables'!$A$7:$A$100000,$A11,'DataTables'!$D$7:$D$100000) | AA11: =COUNTIF('Fields'!$A$7:$A$100000,$A11) | AB11: =COUNTIF('LegacyObjects'!$A$7:$A$100000,$A11) | AC11: =COUNTIF('Warnings'!$A$7:$A$100000,$A11) | AD11: =IF($E11="Parsed",I11*'Totals'!$C$77+J11*'Totals'!$C$78+K11*'Totals'!$C$79+L11*'Totals'!$C$80+M11*'Totals'!$C$81+O11*'Totals'!$C$82+P11*'Totals'!$C$83+Q11*'Totals'!$C$84+S11*'Totals'!$C$85+V11*'Totals'!$C$86+W11*'Totals'!$C$87+X11*'Totals'!$C$88+AB11*'Totals'!$C$89+T11*'Totals'!$C$90+U11*'Totals'!$C$91,0) | AE11: =IF($E11<>"Parsed","-",IF(AD11>='Totals'!$C$94,"High",IF(AD11>='Totals'!$C$93,"Medium","Low")))
A12: TryExtensions | B12: TryExtensions | C12: TryExtensions.qvf | D12: 0.2 | E12: Parsed | F12: 2.1.1 | G12: 2015-11-29 22:54:00 | H12: Yes | I12: =COUNTIF('Sheets'!$A$7:$A$100000,$A12) | J12: =COUNTIF('Visualizations'!$A$7:$A$100000,$A12) | K12: =COUNTIF('MasterMeasures'!$A$7:$A$100000,$A12) | L12: =COUNTIFS('MasterMeasures'!$A$7:$A$100000,$A12,'MasterMeasures'!$G$7:$G$100000,"Yes") | M12: =COUNTIFS('MasterMeasures'!$A$7:$A$100000,$A12,'MasterMeasures'!$H$7:$H$100000,"Yes") | N12: =COUNTIFS('MasterMeasures'!$A$7:$A$100000,$A12,'MasterMeasures'!$K$7:$K$100000,"High") | O12: =COUNTIF('MasterDimensions'!$A$7:$A$100000,$A12) | P12: =COUNTIFS('MasterDimensions'!$A$7:$A$100000,$A12,'MasterDimensions'!$E$7:$E$100000,"Drill-down") | Q12: =COUNTIF('MasterVisualizations'!$A$7:$A$100000,$A12) | R12: =COUNTIF('Variables'!$A$7:$A$100000,$A12) | S12: =COUNTIFS('Variables'!$A$7:$A$100000,$A12,'Variables'!$F$7:$F$100000,"Yes") | T12: =COUNTIF('Bookmarks'!$A$7:$A$100000,$A12) | U12: =COUNTIF('Stories'!$A$7:$A$100000,$A12) | V12: =COUNTIF('LoadScript'!$A$7:$A$100000,$A12) | W12: =SUMIF('LoadScript'!$A$7:$A$100000,$A12,'LoadScript'!$E$7:$E$100000) | X12: =SUMIF('DataSources'!$A$7:$A$100000,$A12,'DataSources'!$F$7:$F$100000) | Y12: =COUNTIF('DataTables'!$A$7:$A$100000,$A12) | Z12: =SUMIF('DataTables'!$A$7:$A$100000,$A12,'DataTables'!$D$7:$D$100000) | AA12: =COUNTIF('Fields'!$A$7:$A$100000,$A12) | AB12: =COUNTIF('LegacyObjects'!$A$7:$A$100000,$A12) | AC12: =COUNTIF('Warnings'!$A$7:$A$100000,$A12) | AD12: =IF($E12="Parsed",I12*'Totals'!$C$77+J12*'Totals'!$C$78+K12*'Totals'!$C$79+L12*'Totals'!$C$80+M12*'Totals'!$C$81+O12*'Totals'!$C$82+P12*'Totals'!$C$83+Q12*'Totals'!$C$84+S12*'Totals'!$C$85+V12*'Totals'!$C$86+W12*'Totals'!$C$87+X12*'Totals'!$C$88+AB12*'Totals'!$C$89+T12*'Totals'!$C$90+U12*'Totals'!$C$91,0) | AE12: =IF($E12<>"Parsed","-",IF(AD12>='Totals'!$C$94,"High",IF(AD12>='Totals'!$C$93,"Medium","Low")))
A13: Tutorial creazione nuova app | B13: Tutorial creazione nuova app | C13: Tutorial creazione nuova app.qvf | D13: 2.43 | E13: Parsed | F13: 2.1.1 | G13: 2016-01-31 18:25:09 | H13: Yes | I13: =COUNTIF('Sheets'!$A$7:$A$100000,$A13) | J13: =COUNTIF('Visualizations'!$A$7:$A$100000,$A13) | K13: =COUNTIF('MasterMeasures'!$A$7:$A$100000,$A13) | L13: =COUNTIFS('MasterMeasures'!$A$7:$A$100000,$A13,'MasterMeasures'!$G$7:$G$100000,"Yes") | M13: =COUNTIFS('MasterMeasures'!$A$7:$A$100000,$A13,'MasterMeasures'!$H$7:$H$100000,"Yes") | N13: =COUNTIFS('MasterMeasures'!$A$7:$A$100000,$A13,'MasterMeasures'!$K$7:$K$100000,"High") | O13: =COUNTIF('MasterDimensions'!$A$7:$A$100000,$A13) | P13: =COUNTIFS('MasterDimensions'!$A$7:$A$100000,$A13,'MasterDimensions'!$E$7:$E$100000,"Drill-down") | Q13: =COUNTIF('MasterVisualizations'!$A$7:$A$100000,$A13) | R13: =COUNTIF('Variables'!$A$7:$A$100000,$A13) | S13: =COUNTIFS('Variables'!$A$7:$A$100000,$A13,'Variables'!$F$7:$F$100000,"Yes") | T13: =COUNTIF('Bookmarks'!$A$7:$A$100000,$A13) | U13: =COUNTIF('Stories'!$A$7:$A$100000,$A13) | V13: =COUNTIF('LoadScript'!$A$7:$A$100000,$A13) | W13: =SUMIF('LoadScript'!$A$7:$A$100000,$A13,'LoadScript'!$E$7:$E$100000) | X13: =SUMIF('DataSources'!$A$7:$A$100000,$A13,'DataSources'!$F$7:$F$100000) | Y13: =COUNTIF('DataTables'!$A$7:$A$100000,$A13) | Z13: =SUMIF('DataTables'!$A$7:$A$100000,$A13,'DataTables'!$D$7:$D$100000) | AA13: =COUNTIF('Fields'!$A$7:$A$100000,$A13) | AB13: =COUNTIF('LegacyObjects'!$A$7:$A$100000,$A13) | AC13: =COUNTIF('Warnings'!$A$7:$A$100000,$A13) | AD13: =IF($E13="Parsed",I13*'Totals'!$C$77+J13*'Totals'!$C$78+K13*'Totals'!$C$79+L13*'Totals'!$C$80+M13*'Totals'!$C$81+O13*'Totals'!$C$82+P13*'Totals'!$C$83+Q13*'Totals'!$C$84+S13*'Totals'!$C$85+V13*'Totals'!$C$86+W13*'Totals'!$C$87+X13*'Totals'!$C$88+AB13*'Totals'!$C$89+T13*'Totals'!$C$90+U13*'Totals'!$C$91,0) | AE13: =IF($E13<>"Parsed","-",IF(AD13>='Totals'!$C$94,"High",IF(AD13>='Totals'!$C$93,"Medium","Low")))
A14: Tutorial creazione script | B14: Tutorial creazione script | C14: Tutorial creazione script.qvf | D14: 0.2 | E14: Parsed | F14: 2.1.1 | G14: 2016-01-31 23:06:30 | H14: Yes | I14: =COUNTIF('Sheets'!$A$7:$A$100000,$A14) | J14: =COUNTIF('Visualizations'!$A$7:$A$100000,$A14) | K14: =COUNTIF('MasterMeasures'!$A$7:$A$100000,$A14) | L14: =COUNTIFS('MasterMeasures'!$A$7:$A$100000,$A14,'MasterMeasures'!$G$7:$G$100000,"Yes") | M14: =COUNTIFS('MasterMeasures'!$A$7:$A$100000,$A14,'MasterMeasures'!$H$7:$H$100000,"Yes") | N14: =COUNTIFS('MasterMeasures'!$A$7:$A$100000,$A14,'MasterMeasures'!$K$7:$K$100000,"High") | O14: =COUNTIF('MasterDimensions'!$A$7:$A$100000,$A14) | P14: =COUNTIFS('MasterDimensions'!$A$7:$A$100000,$A14,'MasterDimensions'!$E$7:$E$100000,"Drill-down") | Q14: =COUNTIF('MasterVisualizations'!$A$7:$A$100000,$A14) | R14: =COUNTIF('Variables'!$A$7:$A$100000,$A14) | S14: =COUNTIFS('Variables'!$A$7:$A$100000,$A14,'Variables'!$F$7:$F$100000,"Yes") | T14: =COUNTIF('Bookmarks'!$A$7:$A$100000,$A14) | U14: =COUNTIF('Stories'!$A$7:$A$100000,$A14) | V14: =COUNTIF('LoadScript'!$A$7:$A$100000,$A14) | W14: =SUMIF('LoadScript'!$A$7:$A$100000,$A14,'LoadScript'!$E$7:$E$100000) | X14: =SUMIF('DataSources'!$A$7:$A$100000,$A14,'DataSources'!$F$7:$F$100000) | Y14: =COUNTIF('DataTables'!$A$7:$A$100000,$A14) | Z14: =SUMIF('DataTables'!$A$7:$A$100000,$A14,'DataTables'!$D$7:$D$100000) | AA14: =COUNTIF('Fields'!$A$7:$A$100000,$A14) | AB14: =COUNTIF('LegacyObjects'!$A$7:$A$100000,$A14) | AC14: =COUNTIF('Warnings'!$A$7:$A$100000,$A14) | AD14: =IF($E14="Parsed",I14*'Totals'!$C$77+J14*'Totals'!$C$78+K14*'Totals'!$C$79+L14*'Totals'!$C$80+M14*'Totals'!$C$81+O14*'Totals'!$C$82+P14*'Totals'!$C$83+Q14*'Totals'!$C$84+S14*'Totals'!$C$85+V14*'Totals'!$C$86+W14*'Totals'!$C$87+X14*'Totals'!$C$88+AB14*'Totals'!$C$89+T14*'Totals'!$C$90+U14*'Totals'!$C$91,0) | AE14: =IF($E14<>"Parsed","-",IF(AD14>='Totals'!$C$94,"High",IF(AD14>='Totals'!$C$93,"Medium","Low")))

Sheet Sheets
D2: Sheets · every sheet in every app
A5: =HYPERLINK("#'Discovery'!A1","« Back to Discovery") | B5: One row per sheet in every app: title, description, visualizations on it, master-item reuse.
A6: App | B6: # | C6: Sheet ID | D6: Title | E6: Description | F6: Visualizations | G6: Linked to master items | H6: Grid (cols x rows)
A7: Executive Dashboard | B7: 1 | C7: PfKsJK | D7: KPI Dashboard | E7: The KPI Dashboard provides a high-level overview of the company in three areas: expenses, revenue and account receivables. | F7: =COUNTIFS('Visualizations'!$A$7:$A$100000,A7,'Visualizations'!$B$7:$B$100000,C7) | G7: =COUNTIFS('Visualizations'!$A$7:$A$100000,A7,'Visualizations'!$B$7:$B$100000,C7,'Visualizations'!$H$7:$H$100000,"?*") | H7: 24 x 12
A8: Executive Dashboard | B8: 2 | C8: FaQeFa | D8: Sales Analysis | E8: The Sales Analysis sheet allows the user to monitor the company's revenue to ensure it is on target for the year. | F8: =COUNTIFS('Visualizations'!$A$7:$A$100000,A8,'Visualizations'!$B$7:$B$100000,C8) | G8: =COUNTIFS('Visualizations'!$A$7:$A$100000,A8,'Visualizations'!$B$7:$B$100000,C8,'Visualizations'!$H$7:$H$100000,"?*") | H8: 24 x 12
A9: Executive Dashboard | B9: 3 | C9: JsCeVm | D9: Account Receivable Analysis | E9: The Account Receivables Analysis sheet provides sales information and a look at the amount due and days sales outstanding for customers. | F9: =COUNTIFS('Visualizations'!$A$7:$A$100000,A9,'Visualizations'!$B$7:$B$100000,C9) | G9: =COUNTIFS('Visualizations'!$A$7:$A$100000,A9,'Visualizations'!$B$7:$B$100000,C9,'Visualizations'!$H$7:$H$100000,"?*") | H9: 24 x 12
A10: Helpdesk Management | B10: 1 | C10: 1ff88551-9c4d-41e0-b790-37f4c11d3df8 | D10: Dashboard | E10: Quickly analyze the pulse of the Helpdesk organization. See the case priority breakdown, cases by department, cases by type, etc. | F10: =COUNTIFS('Visualizations'!$A$7:$A$100000,A10,'Visualizations'!$B$7:$B$100000,C10) | G10: =COUNTIFS('Visualizations'!$A$7:$A$100000,A10,'Visualizations'!$B$7:$B$100000,C10,'Visualizations'!$H$7:$H$100000,"?*") | H10: 24 x 12
A11: Helpdesk Management | B11: 2 | C11: kHgmg | D11: Performance | E11: See employee resource breakdown for each case. Who has the most open cases? Which employee's average case duration is the longest? | F11: =COUNTIFS('Visualizations'!$A$7:$A$100000,A11,'Visualizations'!$B$7:$B$100000,C11) | G11: =COUNTIFS('Visualizations'!$A$7:$A$100000,A11,'Visualizations'!$B$7:$B$100000,C11,'Visualizations'!$H$7:$H$100000,"?*") | H11: 24 x 12
A12: Helpdesk Management | B12: 3 | C12: VkcYvCR | D12: Case Details | E12: See an overview of each case. Filter by department, type, open cases, closed cases, etc | F12: =COUNTIFS('Visualizations'!$A$7:$A$100000,A12,'Visualizations'!$B$7:$B$100000,C12) | G12: =COUNTIFS('Visualizations'!$A$7:$A$100000,A12,'Visualizations'!$B$7:$B$100000,C12,'Visualizations'!$H$7:$H$100000,"?*") | H12: 24 x 12
A13: Sales Analysis | B13: 1 | C13: RpwpQEp | D13: Il mio nuovo foglio | F13: =COUNTIFS('Visualizations'!$A$7:$A$100000,A13,'Visualizations'!$B$7:$B$100000,C13) | G13: =COUNTIFS('Visualizations'!$A$7:$A$100000,A13,'Visualizations'!$B$7:$B$100000,C13,'Visualizations'!$H$7:$H$100000,"?*") | H13: 24 x 12
A14: TryConfigColorAndAgrField | B14: 1 | C14: yJByFm | D14: Visualizza dati | F14: =COUNTIFS('Visualizations'!$A$7:$A$100000,A14,'Visualizations'!$B$7:$B$100000,C14) | G14: =COUNTIFS('Visualizations'!$A$7:$A$100000,A14,'Visualizations'!$B$7:$B$100000,C14,'Visualizations'!$H$7:$H$100000,"?*") | H14: 24 x 12
A15: TryExtensions | B15: 1 | C15: bEBzp | D15: Hello World | F15: =COUNTIFS('Visualizations'!$A$7:$A$100000,A15,'Visualizations'!$B$7:$B$100000,C15) | G15: =COUNTIFS('Visualizations'!$A$7:$A$100000,A15,'Visualizations'!$B$7:$B$100000,C15,'Visualizations'!$H$7:$H$100000,"?*") | H15: 24 x 12
A16: Tutorial creazione nuova app | B16: 1 | C16: pNfY | D16: Dashboard | F16: =COUNTIFS('Visualizations'!$A$7:$A$100000,A16,'Visualizations'!$B$7:$B$100000,C16) | G16: =COUNTIFS('Visualizations'!$A$7:$A$100000,A16,'Visualizations'!$B$7:$B$100000,C16,'Visualizations'!$H$7:$H$100000,"?*") | H16: 24 x 12
A17: Tutorial creazione nuova app | B17: 2 | C17: DxxjRM | D17: Product details | F17: =COUNTIFS('Visualizations'!$A$7:$A$100000,A17,'Visualizations'!$B$7:$B$100000,C17) | G17: =COUNTIFS('Visualizations'!$A$7:$A$100000,A17,'Visualizations'!$B$7:$B$100000,C17,'Visualizations'!$H$7:$H$100000,"?*") | H17: 24 x 12
A18: Tutorial creazione nuova app | B18: 3 | C18: dwcu | D18: Customer details | F18: =COUNTIFS('Visualizations'!$A$7:$A$100000,A18,'Visualizations'!$B$7:$B$100000,C18) | G18: =COUNTIFS('Visualizations'!$A$7:$A$100000,A18,'Visualizations'!$B$7:$B$100000,C18,'Visualizations'!$H$7:$H$100000,"?*") | H18: 24 x 12
A19: Tutorial creazione nuova app | B19: 4 | C19: jnJmy | D19: Customer location | F19: =COUNTIFS('Visualizations'!$A$7:$A$100000,A19,'Visualizations'!$B$7:$B$100000,C19) | G19: =COUNTIFS('Visualizations'!$A$7:$A$100000,A19,'Visualizations'!$B$7:$B$100000,C19,'Visualizations'!$H$7:$H$100000,"?*") | H19: 24 x 12

Sheet Visualizations
C2: Visualizations · every object on every sheet
A5: =HYPERLINK("#'Discovery'!A1","« Back to Discovery") | B5: Every object on every sheet (including containers and filter panes): type, title, master visualization link, dimensions, measures, grid position.
A6: App | B6: Sheet ID | C6: Sheet | D6: Object ID | E6: Type | F6: Title | G6: Inside container | H6: Master visualization ID | I6: Master visualization | J6: Dimensions | K6: Measures | L6: # Dim | M6: # Meas | N6: Grid position
A7: Executive Dashboard | B7: PfKsJK | C7: KPI Dashboard | D7: KxdNL | E7: gauge | F7: 'Expenses vs. Target = ' & num(sum({<[Fiscal Year]={$(vYTDYear)}, _HistoryFlag={1}>} ExpenseActual)/sum({<[Fiscal Year]={$(vYTDYear)}, _HistoryFlag={1}>} ExpenseBudget), '#,##0%') | K7: Expenses vs. Target | L7: 0 | M7: 1 | N7: col 0, row 0, 8x4
A8: Executive Dashboard | B8: PfKsJK | C8: KPI Dashboard | D8: tcxTY | E8: gauge | F8: 'Revenue vs Last Year Revenue = '& num(Sum({<[Fiscal Year]={$(=vYTDYear)}, FiscalMonthNum={"<=$(vCurrentMonthNum)"}>}[Sales Price]*[Sales Quantity])/Sum({<[Fiscal Year]={$(=(vYTDYear)-1)}, FiscalMonthNum={"<=$(vCurrentMonthNum)"}>}[Sales Price]*[Sales Quantity]), '#,##0%') | K8: Revenue vs. LY Revenue | L8: 0 | M8: 1 | N8: col 8, row 0, 8x4
A9: Executive Dashboard | B9: PfKsJK | C9: KPI Dashboard | D9: MdpsUpA | E9: gauge | F9: 'Account Receivable Overdue = ' & num((Sum({<[Fiscal Year]={$(vYTDYear)}>} AROpen)-Sum({<[Fiscal Year]={$(vYTDYear)}>} ARCurrent))/Sum({<[Fiscal Year]={$(vYTDYear)}>} AROpen), '#,##0%') | K9: AR % Overdue | L9: 0 | M9: 1 | N9: col 16, row 0, 8x4
A10: Executive Dashboard | B10: PfKsJK | C10: KPI Dashboard | D10: NaKQwM | E10: piechart | F10: Expenses by Accounts | J10: Account | K10: Expense Amount | L10: 1 | M10: 1 | N10: col 0, row 4, 8x5
A11: Executive Dashboard | B11: PfKsJK | C11: KPI Dashboard | D11: ZxDKp | E11: piechart | F11: Revenue by Products | J11: Product Sub Group Desc | K11: Revenue | L11: 1 | M11: 1 | N11: col 8, row 4, 8x5
A12: Executive Dashboard | B12: PfKsJK | C12: KPI Dashboard | D12: ARNmpdM | E12: piechart | F12: Amount Overdue by Customers | J12: Customer | K12: Amount Overdue | L12: 1 | M12: 1 | N12: col 16, row 4, 8x5
A13: Executive Dashboard | B13: PfKsJK | C13: KPI Dashboard | D13: JEBdZz | E13: linechart | F13: Expense Trend | J13: Month | K13: Expense Amount | L13: 1 | M13: 1 | N13: col 0, row 9, 8x3
A14: Executive Dashboard | B14: PfKsJK | C14: KPI Dashboard | D14: GJxgd | E14: linechart | F14: Revenue Trend | J14: Month | K14: Revenue | L14: 1 | M14: 1 | N14: col 8, row 9, 8x3
A15: Executive Dashboard | B15: PfKsJK | C15: KPI Dashboard | D15: QYthJs | E15: linechart | F15: AR Trend | J15: Month | K15: AR Average Balance | L15: 1 | M15: 1 | N15: col 16, row 9, 8x3
A16: Executive Dashboard | B16: JsCeVm | C16: Account Receivable Analysis | D16: YPPUPE | E16: treemap | F16: Revenue by Sales Rep | J16: Segment; Sales Rep Name | K16: Revenue | L16: 2 | M16: 1 | N16: col 0, row 0, 6x12
A17: Executive Dashboard | B17: JsCeVm | C17: Account Receivable Analysis | D17: trePT | E17: gauge | K17: Margin % | L17: 0 | M17: 1 | N17: col 6, row 0, 3x4
A18: Executive Dashboard | B18: JsCeVm | C18: Account Receivable Analysis | D18: ZFaWvw | E18: gauge | K18: Days Sales Outstanding | L18: 0 | M18: 1 | N18: col 6, row 8, 3x4
A19: Executive Dashboard | B19: JsCeVm | C19: Account Receivable Analysis | D19: VARhxUj | E19: gauge | K19: AR % Overdue | L19: 0 | M19: 1 | N19: col 6, row 4, 3x4
A20: Executive Dashboard | B20: JsCeVm | C20: Account Receivable Analysis | D20: BmfQbz | E20: scatterplot | F20: Sales vs Margin | J20: Customer | K20: CY Sales; Margin % | L20: 1 | M20: 2 | N20: col 9, row 0, 8x4
A21: Executive Dashboard | B21: JsCeVm | C21: Account Receivable Analysis | D21: mVPztHm | E21: scatterplot | F21: Amount Overdue vs DSO | J21: Customer | K21: Days Sales Outstanding; Amount Overdue | L21: 1 | M21: 2 | N21: col 9, row 4, 8x4
A22: Executive Dashboard | B22: JsCeVm | C22: Account Receivable Analysis | D22: NeLVr | E22: scatterplot | F22: Avg Sales Per Day vs AR Avg Balance | J22: Customer | K22: AR Average Balance; Avg Sales Per Day | L22: 1 | M22: 2 | N22: col 9, row 8, 8x4
A23: Executive Dashboard | B23: JsCeVm | C23: Account Receivable Analysis | D23: nnkLtpf | E23: table | F23: CY Sales vs LY Sales | J23: Product | K23: CY Sales; LY Sales | L23: 1 | M23: 2 | N23: col 17, row 0, 7x12
A24: Executive Dashboard | B24: FaQeFa | C24: Sales Analysis | D24: fzrxtjq | E24: scatterplot | F24: Sales vs Margin by Sales Rep | J24: Sales Rep Name | K24: Margin %; Revenue | L24: 1 | M24: 2 | N24: col 0, row 1, 12x6
A25: Executive Dashboard | B25: FaQeFa | C25: Sales Analysis | D25: nvqpV | E25: linechart | F25: Average Sales Per Day | J25: Year Month | K25: Avg Sales Per Day | L25: 1 | M25: 1 | N25: col 0, row 7, 12x5
A26: Executive Dashboard | B26: FaQeFa | C26: Sales Analysis | D26: qZPdytp | E26: barchart | F26: 'Total Revenue by Product Group = ' & num(Sum([Sales Quantity]*[Sales Price]), '$#,##0') | J26: Product Sub Group Desc | K26: Revenue | L26: 1 | M26: 1 | N26: col 12, row 1, 12x11
A27: Executive Dashboard | B27: FaQeFa | C27: Sales Analysis | D27: jRMGQG | E27: filterpane | L27: 0 | M27: 0 | N27: col 0, row 0, 24x1
A28: Executive Dashboard | B28: FaQeFa | C28: Sales Analysis | D28: nURpk | E28: listbox | F28: Segment | G28: jRMGQG | J28: Segment | L28: 1 | M28: 0
A29: Executive Dashboard | B29: FaQeFa | C29: Sales Analysis | D29: pdLG | E29: listbox | F29: Region | G29: jRMGQG | J29: Region | L29: 1 | M29: 0
A30: Executive Dashboard | B30: FaQeFa | C30: Sales Analysis | D30: BArut | E30: listbox | F30: Sales Rep Name | G30: jRMGQG | J30: Sales Rep Name | L30: 1 | M30: 0
A31: Executive Dashboard | B31: FaQeFa | C31: Sales Analysis | D31: RdNtA | E31: listbox | F31: Product Group | G31: jRMGQG | J31: Product Group | L31: 1 | M31: 0
A32: Helpdesk Management | B32: VkcYvCR | C32: Case Details | D32: ycppXj | E32: filterpane | F32: Filters | L32: 0 | M32: 0 | N32: col 0, row 0, 24x1
A33: Helpdesk Management | B33: VkcYvCR | C33: Case Details | D33: dEDkpN | E33: listbox | F33: Cases Open/Closed | G33: ycppXj | J33: Cases Open/Closed | L33: 1 | M33: 0
A34: Helpdesk Management | B34: VkcYvCR | C34: Case Details | D34: pKBGKm | E34: listbox | F34: Priority | G34: ycppXj | J34: Priority | L34: 1 | M34: 0
A35: Helpdesk Management | B35: VkcYvCR | C35: Case Details | D35: JEPxkM | E35: listbox | F35: IT Resources | G35: ycppXj | J35: Case Owner | L35: 1 | M35: 0
A36: Helpdesk Management | B36: VkcYvCR | C36: Case Details | D36: WfWFp | E36: listbox | F36: Request Type | G36: ycppXj | J36: Case Record Type | L36: 1 | M36: 0
A37: Helpdesk Management | B37: VkcYvCR | C37: Case Details | D37: LZqevwG | E37: listbox | F37: Department | G37: ycppXj | J37: Case Owner Group | L37: 1 | M37: 0
A38: Helpdesk Management | B38: VkcYvCR | C38: Case Details | D38: rJFbvG | E38: table | F38: ='Case Details: ' & Num(Count(distinct %CaseId),'#,##0') & ' Cases' | J38: CaseNumber; Subject; Case Owner; Status; Case Created Date; Case Closed Date | K38: Case Duration (dd hh:mm) | L38: 6 | M38: 1 | N38: col 0, row 1, 24x11
A39: Helpdesk Management | B39: kHgmg | C39: Performance | D39: uETyGUP | E39: table | F39: Resource Details | J39: Case Owner; Status | K39: Tenure; Open Cases; Closed Cases; Total Cases; Open Cases - High; Open Cases - Medium; Open Cases - Low; Avg Case Duration | L39: 2 | M39: 8 | N39: col 0, row 6, 24x6
A40: Helpdesk Management | B40: kHgmg | C40: Performance | D40: xfvKMP | E40: linechart | F40: New Cases by Department over time | J40: YearMonth; Department | K40: Cumulative New Cases | L40: 2 | M40: 1 | N40: col 8, row 0, 16x6
A41: Helpdesk Management | B41: kHgmg | C41: Performance | D41: PAppmU | E41: piechart | F41: Open Cases by Age | J41: Case Timetable | K41: Open Cases | L41: 1 | M41: 1 | N41: col 0, row 0, 8x6
A42: Helpdesk Management | B42: 1ff88551-9c4d-41e0-b790-37f4c11d3df8 | C42: Dashboard | D42: a5e0f12c-38f5-4da9-8f3f-0e4566b28398 | E42: barchart | F42: Avg Case Resolution Time (Days) | J42: Case Owner Group | K42: Avg Case Duration | L42: 1 | M42: 1 | N42: col 16, row 0, 8x7
A43: Helpdesk Management | B43: 1ff88551-9c4d-41e0-b790-37f4c11d3df8 | C43: Dashboard | D43: 298bbd6d-f23d-4469-94a2-df243d680e0c | E43: scatterplot | F43: Open Cases vs Duration | J43: Case Owner | K43: Avg Case Duration; Open Cases | L43: 1 | M43: 2 | N43: col 5, row 0, 11x7
...

Sheet MasterMeasures
C2: Master measures · the measure libraries
A5: =HYPERLINK("#'Discovery'!A1","« Back to Discovery") | B5: Library measures with the full expression, complexity flags and how often they are used.
A6: App | B6: ID | C6: Label | D6: Expression | E6: Description | F6: Tags | G6: Set analysis | H6: Aggr() | I6: If / Pick / Match | J6: $() expansion | K6: Complexity | L6: Used in visualizations | M6: Expression length | N6: Found by
A7: Executive Dashboard | B7: NPPsJt | C7: Revenue | D7: Sum([Sales Quantity]*[Sales Price]) | E7: The revenue. | G7: No | H7: No | I7: No | J7: No | K7: Low | L7: =COUNTIFS('MasterItemUsage'!$A$7:$A$100000,A7,'MasterItemUsage'!$F$7:$F$100000,B7) | M7: 35 | N7: qlik-parser
A8: Executive Dashboard | B8: SLJUwQj | C8: Sales Quantity | D8: Sum([Sales Quantity]) | E8: The quantity sold. | G8: No | H8: No | I8: No | J8: No | K8: Low | L8: =COUNTIFS('MasterItemUsage'!$A$7:$A$100000,A8,'MasterItemUsage'!$F$7:$F$100000,B8) | M8: 21 | N8: qlik-parser
A9: Executive Dashboard | B9: mwwzJ | C9: Expenses vs. Target | D9: sum({<[Fiscal Year]={$(vYTDYear)}, _HistoryFlag={1}>} ExpenseActual)/sum({<[Fiscal Year]={$(vYTDYear)}, _HistoryFlag={1}>} ExpenseBudget) | E9: Ratio of actual expenses compared to the target expenses. | G9: Yes | H9: No | I9: No | J9: Yes | K9: Medium | L9: =COUNTIFS('MasterItemUsage'!$A$7:$A$100000,A9,'MasterItemUsage'!$F$7:$F$100000,B9) | M9: 137 | N9: qlik-parser
A10: Executive Dashboard | B10: bUft | C10: Expense as % of Sale | D10: If(Sum(ExpenseActual)>0,Sum(ExpenseActual),0) | E10: Actual expenses. | G10: No | H10: No | I10: Yes | J10: No | K10: Medium | L10: =COUNTIFS('MasterItemUsage'!$A$7:$A$100000,A10,'MasterItemUsage'!$F$7:$F$100000,B10) | M10: 45 | N10: qlik-parser
A11: Executive Dashboard | B11: napvtJ | C11: Expense Amount | D11: sum(ExpenseActual) | E11: Expenses. | G11: No | H11: No | I11: No | J11: No | K11: Low | L11: =COUNTIFS('MasterItemUsage'!$A$7:$A$100000,A11,'MasterItemUsage'!$F$7:$F$100000,B11) | M11: 18 | N11: qlik-parser
A12: Executive Dashboard | B12: jpcvPf | C12: Expense (New Calculation) | D12: Sum({<[Fiscal Year]={$(vYear)}>}ExpenseActual)/1000 | E12: Expenses in thousands. | G12: Yes | H12: No | I12: No | J12: Yes | K12: Medium | L12: =COUNTIFS('MasterItemUsage'!$A$7:$A$100000,A12,'MasterItemUsage'!$F$7:$F$100000,B12) | M12: 51 | N12: qlik-parser
A13: Executive Dashboard | B13: FDPQYx | C13: AR % Overdue | D13: (Sum({<[Fiscal Year]={$(vYTDYear)}>} AROpen)-Sum({<[Fiscal Year]={$(vYTDYear)}>} ARCurrent))/Sum({<[Fiscal Year]={$(vYTDYear)}>} AROpen) | E13: The percentage overdue year to date. | G13: Yes | H13: No | I13: No | J13: Yes | K13: Medium | L13: =COUNTIFS('MasterItemUsage'!$A$7:$A$100000,A13,'MasterItemUsage'!$F$7:$F$100000,B13) | M13: 136 | N13: qlik-parser
A14: Executive Dashboard | B14: w | C14: Inventory Amount | D14: Sum(StockOH*CostPrice) | E14: The amount in inventory ($). | G14: No | H14: No | I14: No | J14: No | K14: Low | L14: =COUNTIFS('MasterItemUsage'!$A$7:$A$100000,A14,'MasterItemUsage'!$F$7:$F$100000,B14) | M14: 22 | N14: qlik-parser
A15: Executive Dashboard | B15: sgeyqn | C15: Margin Amount | D15: (Sum([Sales Quantity]*[Sales Price])) - (Sum([Sales Cost Amount])) | E15: The margin amount. | G15: No | H15: No | I15: No | J15: No | K15: Low | L15: =COUNTIFS('MasterItemUsage'!$A$7:$A$100000,A15,'MasterItemUsage'!$F$7:$F$100000,B15) | M15: 66 | N15: qlik-parser
A16: Executive Dashboard | B16: RRcCqu | C16: # of Cust AR60+ | D16: if( Sum ([AR60+])>0, count ( distinct [Customer Number])) | E16: Number of customers overdue by 60 or more days. | G16: No | H16: No | I16: Yes | J16: No | K16: Medium | L16: =COUNTIFS('MasterItemUsage'!$A$7:$A$100000,A16,'MasterItemUsage'!$F$7:$F$100000,B16) | M16: 57 | N16: qlik-parser
A17: Executive Dashboard | B17: jnjgaPY | C17: Cost (Total) | D17: Sum([Sales Cost Amount]) | E17: Cost amount. | G17: No | H17: No | I17: No | J17: No | K17: Low | L17: =COUNTIFS('MasterItemUsage'!$A$7:$A$100000,A17,'MasterItemUsage'!$F$7:$F$100000,B17) | M17: 24 | N17: qlik-parser
A18: Executive Dashboard | B18: pVTm | C18: AR Average Balance | D18: Sum (ARAvgBal) | E18: Average account receivables balance. | G18: No | H18: No | I18: No | J18: No | K18: Low | L18: =COUNTIFS('MasterItemUsage'!$A$7:$A$100000,A18,'MasterItemUsage'!$F$7:$F$100000,B18) | M18: 14 | N18: qlik-parser
... A55: Helpdesk Management | B55: NRbtFne | C55: Most Cases | D55: firstsortedvalue( Priority, -Aggr(Count({<[Cases Open/Closed]={'Open Cases'}>}Distinct [%CaseId] ),[Case Owner Group],Priority)) | E55: The priority group with the most open cases. | G55: Yes | H55: Yes | I55: No | J55: No | K55: High | L55: =COUNTIFS('MasterItemUsage'!$A$7:$A$100000,A55,'MasterItemUsage'!$F$7:$F$100000,B55) | M55: 128 | N55: qlik-parser
A56: Tutorial creazione nuova app | B56: pHjKV | C56: Sales | D56: Sum(Sales) | G56: No | H56: No | I56: No | J56: No | K56: Low | L56: =COUNTIFS('MasterItemUsage'!$A$7:$A$100000,A56,'MasterItemUsage'!$F$7:$F$100000,B56) | M56: 10 | N56: qlik-parser
A57: Tutorial creazione nuova app | B57: SKnVL | C57: Margin Percent | D57: (Sum(Sales) - Sum(Cost)) / Sum(Sales) | G57: No | H57: No | I57: No | J57: No | K57: Low | L57: =COUNTIFS('MasterItemUsage'!$A$7:$A$100000,A57,'MasterItemUsage'!$F$7:$F$100000,B57) | M57: 37 | N57: qlik-parser
A58: Tutorial creazione nuova app | B58: xNwJu | C58: Margin | D58: Sum(Margin) | G58: No | H58: No | I58: No | J58: No | K58: Low | L58: =COUNTIFS('MasterItemUsage'!$A$7:$A$100000,A58,'MasterItemUsage'!$F$7:$F$100000,B58) | M58: 11 | N58: qlik-parser
A59: Tutorial creazione nuova app | B59: CdSMz | C59: Quantity | D59: Sum([Sales Qty]) | G59: No | H59: No | I59: No | J59: No | K59: Low | L59: =COUNTIFS('MasterItemUsage'!$A$7:$A$100000,A59,'MasterItemUsage'!$F$7:$F$100000,B59) | M59: 16 | N59: qlik-parser
A60: Tutorial creazione nuova app | B60: LsPLsq | C60: # of Invoices | D60: Count(Distinct([Invoice Number])) | G60: No | H60: No | I60: No | J60: No | K60: Low | L60: =COUNTIFS('MasterItemUsage'!$A$7:$A$100000,A60,'MasterItemUsage'!$F$7:$F$100000,B60) | M60: 33 | N60: qlik-parser
A61: Tutorial creazione nuova app | B61: VaEaEf | C61: Average Sales per Invoice | D61: Sum(Sales)/Count(Distinct([Invoice Number])) | G61: No | H61: No | I61: No | J61: No | K61: Low | L61: =COUNTIFS('MasterItemUsage'!$A$7:$A$100000,A61,'MasterItemUsage'!$F$7:$F$100000,B61) | M61: 44 | N61: qlik-parser

Sheet MasterDimensions
C2: Master dimensions · the dimension libraries
A5: =HYPERLINK("#'Discovery'!A1","« Back to Discovery") | B5: Library dimensions: fields, single or drill-down, usage.
A6: App | B6: ID | C6: Label | D6: Fields | E6: Kind | F6: Description | G6: Tags | H6: Used in visualizations | I6: Found by
A7: Executive Dashboard | B7: EzubBQ | C7: Customer Number | D7: Customer Number | E7: Single | H7: =COUNTIFS('MasterItemUsage'!$A$7:$A$100000,A7,'MasterItemUsage'!$F$7:$F$100000,B7) | I7: qlik-parser
A8: Executive Dashboard | B8: XFhtUb | C8: Sales Rep Name | D8: Sales Rep Name | E8: Single | H8: =COUNTIFS('MasterItemUsage'!$A$7:$A$100000,A8,'MasterItemUsage'!$F$7:$F$100000,B8) | I8: qlik-parser
A9: Executive Dashboard | B9: ANYTpUm | C9: Product Type Desc | D9: Product Type Desc | E9: Single | G9: Product Hierarchy | H9: =COUNTIFS('MasterItemUsage'!$A$7:$A$100000,A9,'MasterItemUsage'!$F$7:$F$100000,B9) | I9: qlik-parser
A10: Executive Dashboard | B10: pmresb | C10: Product | D10: Line Desc 1 | E10: Single | G10: Product Hierarchy | H10: =COUNTIFS('MasterItemUsage'!$A$7:$A$100000,A10,'MasterItemUsage'!$F$7:$F$100000,B10) | I10: qlik-parser
A11: Executive Dashboard | B11: rAWLLGj | C11: Product Group | D11: Product Group Desc | E11: Single | G11: Product Hierarchy | H11: =COUNTIFS('MasterItemUsage'!$A$7:$A$100000,A11,'MasterItemUsage'!$F$7:$F$100000,B11) | I11: qlik-parser
A12: Executive Dashboard | B12: PjEUh | C12: Order Number | D12: Order Number | E12: Single | H12: =COUNTIFS('MasterItemUsage'!$A$7:$A$100000,A12,'MasterItemUsage'!$F$7:$F$100000,B12) | I12: qlik-parser
A13: Executive Dashboard | B13: nrxFRV | C13: Account Group | D13: AccountGroupDesc | E13: Single | H13: =COUNTIFS('MasterItemUsage'!$A$7:$A$100000,A13,'MasterItemUsage'!$F$7:$F$100000,B13) | I13: qlik-parser
A14: Executive Dashboard | B14: jgxpDbw | C14: Region | D14: Region | E14: Single | H14: =COUNTIFS('MasterItemUsage'!$A$7:$A$100000,A14,'MasterItemUsage'!$F$7:$F$100000,B14) | I14: qlik-parser
A15: Executive Dashboard | B15: HnEfUp | C15: Year Month | D15: YYYYMM | E15: Single | H15: =COUNTIFS('MasterItemUsage'!$A$7:$A$100000,A15,'MasterItemUsage'!$F$7:$F$100000,B15) | I15: qlik-parser
A16: Executive Dashboard | B16: DcuPcq | C16: Product Sub Group Desc | D16: Product Sub Group Desc | E16: Single | F16: Product sub group description | G16: Product Hierarchy | H16: =COUNTIFS('MasterItemUsage'!$A$7:$A$100000,A16,'MasterItemUsage'!$F$7:$F$100000,B16) | I16: qlik-parser
A17: Executive Dashboard | B17: aLVsP | C17: Account | D17: AccountDesc | E17: Single | F17: Account description. | H17: =COUNTIFS('MasterItemUsage'!$A$7:$A$100000,A17,'MasterItemUsage'!$F$7:$F$100000,B17) | I17: qlik-parser
A18: Executive Dashboard | B18: pcZcGjn | C18: Customer | D18: Customer | E18: Single | H18: =COUNTIFS('MasterItemUsage'!$A$7:$A$100000,A18,'MasterItemUsage'!$F$7:$F$100000,B18) | I18: qlik-parser
A19: Executive Dashboard | B19: RJRD | C19: ARAge | D19: ARAge | E19: Single | F19: Age of account receivable. | H19: =COUNTIFS('MasterItemUsage'!$A$7:$A$100000,A19,'MasterItemUsage'!$F$7:$F$100000,B19) | I19: qlik-parser
A20: Executive Dashboard | B20: jcDdm | C20: Order Status | D20: Order Status | E20: Single | H20: =COUNTIFS('MasterItemUsage'!$A$7:$A$100000,A20,'MasterItemUsage'!$F$7:$F$100000,B20) | I20: qlik-parser
A21: Executive Dashboard | B21: AswNnUE | C21: Year | D21: Fiscal Year | E21: Single | H21: =COUNTIFS('MasterItemUsage'!$A$7:$A$100000,A21,'MasterItemUsage'!$F$7:$F$100000,B21) | I21: qlik-parser
A22: Executive Dashboard | B22: FYkzzR | C22: Customer Type | D22: Customer Type | E22: Single | H22: =COUNTIFS('MasterItemUsage'!$A$7:$A$100000,A22,'MasterItemUsage'!$F$7:$F$100000,B22) | I22: qlik-parser
A23: Executive Dashboard | B23: wLJmmJn | C23: Segment | D23: SegmentDesc | E23: Single | H23: =COUNTIFS('MasterItemUsage'!$A$7:$A$100000,A23,'MasterItemUsage'!$F$7:$F$100000,B23) | I23: qlik-parser
A24: Executive Dashboard | B24: eMukN | C24: Quarter | D24: Fiscal Quarter | E24: Single | H24: =COUNTIFS('MasterItemUsage'!$A$7:$A$100000,A24,'MasterItemUsage'!$F$7:$F$100000,B24) | I24: qlik-parser
A25: Executive Dashboard | B25: dyCEjG | C25: Month | D25: FiscalMonth | E25: Single | H25: =COUNTIFS('MasterItemUsage'!$A$7:$A$100000,A25,'MasterItemUsage'!$F$7:$F$100000,B25) | I25: qlik-parser
A26: Executive Dashboard | B26: jxuDwx | C26: Inventory Turns | D26: ClassTurns | E26: Single | F26: The number of times inventory is sold or used in a year. | H26: =COUNTIFS('MasterItemUsage'!$A$7:$A$100000,A26,'MasterItemUsage'!$F$7:$F$100000,B26) | I26: qvf-app
A27: Executive Dashboard | B27: QuWSp | C27: Account Drill | D27: AccountDesc, AccountGroupDesc | E27: Drill-down | F27: Drill down from the account description to the account group description. | H27: =COUNTIFS('MasterItemUsage'!$A$7:$A$100000,A27,'MasterItemUsage'!$F$7:$F$100000,B27) | I27: qvf-app
A28: Helpdesk Management | B28: wpUyjc | C28: Cases Open/Closed | D28: Cases Open/Closed | E28: Single | F28: Open and closed cases. | H28: =COUNTIFS('MasterItemUsage'!$A$7:$A$100000,A28,'MasterItemUsage'!$F$7:$F$100000,B28) | I28: qlik-parser
A29: Helpdesk Management | B29: RBBKJP | C29: Department | D29: Case Owner Group | E29: Single | H29: =COUNTIFS('MasterItemUsage'!$A$7:$A$100000,A29,'MasterItemUsage'!$F$7:$F$100000,B29) | I29: qlik-parser
A30: Helpdesk Management | B30: hyeGht | C30: Priority | D30: Priority | E30: Single | F30: Case priority. | H30: =COUNTIFS('MasterItemUsage'!$A$7:$A$100000,A30,'MasterItemUsage'!$F$7:$F$100000,B30) | I30: qlik-parser
A31: Helpdesk Management | B31: Bbdkpp | C31: Request Type | D31: Case Record Type | E31: Single | F31: Type of helpdesk request. | H31: =COUNTIFS('MasterItemUsage'!$A$7:$A$100000,A31,'MasterItemUsage'!$F$7:$F$100000,B31) | I31: qlik-parser
A32: Helpdesk Management | B32: krpjsE | C32: %OwnerId | D32: %OwnerId | E32: Single | F32: The Owner ID. | H32: =COUNTIFS('MasterItemUsage'!$A$7:$A$100000,A32,'MasterItemUsage'!$F$7:$F$100000,B32) | I32: qlik-parser
A33: Helpdesk Management | B33: rfQk | C33: IT Resources | D33: Case Owner | E33: Single | F33: IT resource. | H33: =COUNTIFS('MasterItemUsage'!$A$7:$A$100000,A33,'MasterItemUsage'!$F$7:$F$100000,B33) | I33: qlik-parser
A34: Helpdesk Management | B34: sEavA | C34: %CaseId | D34: %CaseId | E34: Single | F34: The Case ID. | H34: =COUNTIFS('MasterItemUsage'!$A$7:$A$100000,A34,'MasterItemUsage'!$F$7:$F$100000,B34) | I34: qlik-parser
A35: Helpdesk Management | B35: jySjA | C35: Year | D35: Year | E35: Single | H35: =COUNTIFS('MasterItemUsage'!$A$7:$A$100000,A35,'MasterItemUsage'!$F$7:$F$100000,B35) | I35: qlik-parser

Sheet MasterVisualizations
C2: Master visualizations · reusable charts
A5: =HYPERLINK("#'Discovery'!A1","« Back to Discovery") | B5: Reusable library charts with their dimensions, measures and usage.
A6: App | B6: ID | C6: Title | D6: Chart type | E6: Description | F6: Dimensions | G6: Measures | H6: Used on sheets
A7: Executive Dashboard | B7: tmaqpf | C7: Revenue by Product | D7: treemap | E7: View revenue by product. | F7: Product | G7: Revenue | H7: =COUNTIFS('MasterItemUsage'!$A$7:$A$100000,A7,'MasterItemUsage'!$F$7:$F$100000,B7)
A8: Executive Dashboard | B8: JZMrdb | C8: Product Inventory Turns, Amount and Margin% | D8: table | E8: Products in inventory and their dollar value, margin and number of inventory turns. | F8: Product; Inventory Turns | G8: Inventory Amount; Margin % | H8: =COUNTIFS('MasterItemUsage'!$A$7:$A$100000,A8,'MasterItemUsage'!$F$7:$F$100000,B8)
A9: Executive Dashboard | B9: BHTXyNM | C9: Expenses as % Sales | D9: piechart | E9: The expenses as a percentage of the sales. | F9: Account | G9: Expenses % of Sales | H9: =COUNTIFS('MasterItemUsage'!$A$7:$A$100000,A9,'MasterItemUsage'!$F$7:$F$100000,B9)
A10: Executive Dashboard | B10: pDKRhr | C10: Customer Revenue vs. Expense | D10: scatterplot | E10: Correlation between customer revenue and expense amount. | F10: Customer | G10: Expense Amount; Revenue | H10: =COUNTIFS('MasterItemUsage'!$A$7:$A$100000,A10,'MasterItemUsage'!$F$7:$F$100000,B10)
A11: Executive Dashboard | B11: FDJPm | C11: Cost Center Report (000s) | D11: table | E11: Expense details such as Account Group, account, Expenses and Budget. | F11: Account Group; Account | G11: Expense 2012; Budget; Expenses 2013 | H11: =COUNTIFS('MasterItemUsage'!$A$7:$A$100000,A11,'MasterItemUsage'!$F$7:$F$100000,B11)
A12: Executive Dashboard | B12: nRxXG | C12: Onhand Inventory $ (sorted by Sales Qty) | D12: barchart | E12: Inventory that is available to be sold. | F12: Product | G12: Inventory Amount | H12: =COUNTIFS('MasterItemUsage'!$A$7:$A$100000,A12,'MasterItemUsage'!$F$7:$F$100000,B12)
A13: Tutorial creazione nuova app | B13: rmBWDa | C13: Period | D13: filterpane | H13: =COUNTIFS('MasterItemUsage'!$A$7:$A$100000,A13,'MasterItemUsage'!$F$7:$F$100000,B13)
A14: Tutorial creazione nuova app | B14: ZvUFrB | C14: Region | D14: filterpane | H14: =COUNTIFS('MasterItemUsage'!$A$7:$A$100000,A14,'MasterItemUsage'!$F$7:$F$100000,B14)
A15: Tutorial creazione nuova app | B15: ZJhRsc | C15: Manager | D15: filterpane | H15: =COUNTIFS('MasterItemUsage'!$A$7:$A$100000,A15,'MasterItemUsage'!$F$7:$F$100000,B15)
A16: Tutorial creazione nuova app | B16: GbHREb | C16: City | D16: filterpane | H16: =COUNTIFS('MasterItemUsage'!$A$7:$A$100000,A16,'MasterItemUsage'!$F$7:$F$100000,B16)
A17: Tutorial creazione nuova app | B17: LsAsQkp | C17: Customer | D17: filterpane | H17: =COUNTIFS('MasterItemUsage'!$A$7:$A$100000,A17,'MasterItemUsage'!$F$7:$F$100000,B17)

Sheet MasterItemUsage
C2: Master item usage · which visualization uses which master item
A5: =HYPERLINK("#'Discovery'!A1","« Back to Discovery") | B5: One row per link from a visualization to a master item; feeds the usage counts.
A6: App | B6: Visualization ID | C6: Visualization type | D6: Sheet | E6: Master item kind | F6: Master item ID | G6: Master item
A7: Executive Dashboard | B7: KxdNL | C7: gauge | D7: KPI Dashboard | E7: Master measure | F7: mwwzJ | G7: Expenses vs. Target
A8: Executive Dashboard | B8: tcxTY | C8: gauge | D8: KPI Dashboard | E8: Master measure | F8: STSDYR | G8: Revenue vs. LY Revenue
A9: Executive Dashboard | B9: MdpsUpA | C9: gauge | D9: KPI Dashboard | E9: Master measure | F9: FDPQYx | G9: AR % Overdue
A10: Executive Dashboard | B10: NaKQwM | C10: piechart | D10: KPI Dashboard | E10: Master dimension | F10: aLVsP | G10: Account
A11: Executive Dashboard | B11: NaKQwM | C11: piechart | D11: KPI Dashboard | E11: Master measure | F11: napvtJ | G11: Expense Amount
A12: Executive Dashboard | B12: ZxDKp | C12: piechart | D12: KPI Dashboard | E12: Master dimension | F12: DcuPcq | G12: Product Sub Group Desc
A13: Executive Dashboard | B13: ZxDKp | C13: piechart | D13: KPI Dashboard | E13: Master measure | F13: NPPsJt | G13: Revenue
A14: Executive Dashboard | B14: ARNmpdM | C14: piechart | D14: KPI Dashboard | E14: Master dimension | F14: pcZcGjn | G14: Customer
A15: Executive Dashboard | B15: ARNmpdM | C15: piechart | D15: KPI Dashboard | E15: Master measure | F15: vLRMZz | G15: Amount Overdue
A16: Executive Dashboard | B16: JEBdZz | C16: linechart | D16: KPI Dashboard | E16: Master dimension | F16: dyCEjG | G16: Month
A17: Executive Dashboard | B17: JEBdZz | C17: linechart | D17: KPI Dashboard | E17: Master measure | F17: napvtJ | G17: Expense Amount
... A111: Tutorial creazione nuova app | B111: qbVaPgL | C111: map | D111: Customer location | E111: Master measure | F111: pHjKV | G111: Sales

Sheet Variables
C2: Variables · script and user variables
A5: =HYPERLINK("#'Discovery'!A1","« Back to Discovery") | B5: Script and user variables, their definitions and whether they are expressions.
A6: App | B6: Name | C6: Definition | D6: Comment | E6: Value | F6: Is expression (=) | G6: Script created | H6: List | I6: ID | J6: Found by
A7: Executive Dashboard | B7: CD | C7: D: | E7: NaN | F7: No | G7: Yes | H7: qvapp_variablelist | I7: 8ebc9e1d-55c2-453f-8e61-1f5e86abb831 | J7: qvf-app
A8: Executive Dashboard | B8: QvPath | C8: C:\Users\cbo\Downloads | E8: NaN | F8: No | G8: Yes | H8: qvapp_variablelist | I8: 746b2cd9-ce56-49a4-8bc5-76bb7c6dd788 | J8: qvf-app
A9: Executive Dashboard | B9: QvRoot | C9: C: | E9: NaN | F9: No | G9: Yes | H9: qvapp_variablelist | I9: 3ceede56-2ab6-46fa-a484-5e24ba7397c3 | J9: qvf-app
A10: Executive Dashboard | B10: QvWorkPath | C10: C:/Users/cbo/Documents/Qlik/QlikView/Apps | E10: NaN | F10: No | G10: Yes | H10: qvapp_variablelist | I10: 9d1ea17f-279e-4027-8d70-efb768ada910 | J10: qvf-app
A11: Executive Dashboard | B11: QvWorkRoot | C11: C: | E11: NaN | F11: No | G11: Yes | H11: qvapp_variablelist | I11: 1fff8abb-95e0-472b-9df7-6b425ed931eb | J11: qvf-app
A12: Executive Dashboard | B12: WinPath | C12: C:\Windows | E12: NaN | F12: No | G12: Yes | H12: qvapp_variablelist | I12: 8a7d43e5-a38e-492f-bdad-e722c5b36285 | J12: qvf-app
A13: Executive Dashboard | B13: WinRoot | C13: C: | E13: NaN | F13: No | G13: Yes | H13: qvapp_variablelist | I13: 52aa1e48-8073-4734-a953-555e898549a0 | J13: qvf-app
A14: Executive Dashboard | B14: ErrorMode | E14: 1 | F14: No | G14: Yes | H14: qvapp_variablelist | I14: bcee93bf-0c51-4542-acc1-049e6bba0655 | J14: qvf-app
A15: Executive Dashboard | B15: StripComments | E15: 1 | F15: No | G15: Yes | H15: qvapp_variablelist | I15: 216bafe6-fe53-4fd0-acef-ebd0e10ed759 | J15: qvf-app
A16: Executive Dashboard | B16: OpenUrlTimeout | E16: 86400 | F16: No | G16: Yes | H16: qvapp_variablelist | I16: 9ed380d2-e9d5-4419-9486-d497be948e37 | J16: qvf-app
A17: Executive Dashboard | B17: ScriptErrorCount | C17: 0 | E17: 0 | F17: No | G17: Yes | H17: qvapp_variablelist | I17: 850fa7eb-68af-44a3-8bf7-eaeadfdd42d2 | J17: qvf-app
A18: Executive Dashboard | B18: ScriptErrorList | E18: NaN | F18: No | G18: Yes | H18: qvapp_variablelist | I18: 39193e79-7c97-4d9c-b90d-bcf1ebbe7bf0 | J18: qvf-app
A19: Executive Dashboard | B19: ScriptError | E19: 0 | F19: No | G19: Yes | H19: qvapp_variablelist | I19: 1ec56f5d-a22e-4608-a045-9f492fd2db75 | J19: qvf-app
A20: Executive Dashboard | B20: ThousandSep | C20: , | E20: NaN | F20: No | G20: Yes | H20: qvapp_variablelist | I20: 747f56fa-948a-45a1-95f8-2b1f4551366c | J20: qvf-app
A21: Executive Dashboard | B21: DecimalSep | C21: . | E21: NaN | F21: No | G21: Yes | H21: qvapp_variablelist | I21: c85be7aa-6b92-4e86-bbb2-31d344d69267 | J21: qvf-app
A22: Executive Dashboard | B22: MoneyThousandSep | C22: , | E22: NaN | F22: No | G22: Yes | H22: qvapp_variablelist | I22: fd4da8fb-05ba-4cf9-af49-ab7a7a09cd21 | J22: qvf-app
A23: Executive Dashboard | B23: MoneyDecimalSep | C23: . | E23: NaN | F23: No | G23: Yes | H23: qvapp_variablelist | I23: 96ec746a-5f74-4243-86b7-28d9d0319184 | J23: qvf-app
A24: Executive Dashboard | B24: MoneyFormat | C24: $#,##0.00;($#,##0.00) | E24: NaN | F24: No | G24: Yes | H24: qvapp_variablelist | I24: e48d23bd-2e5b-4ec4-a204-36c8a8e88f98 | J24: qvf-app
A25: Executive Dashboard | B25: TimeFormat | C25: h:mm:ss TT | E25: NaN | F25: No | G25: Yes | H25: qvapp_variablelist | I25: 1d9dad3c-fd6d-4db3-a668-c77d5526c4c5 | J25: qvf-app
A26: Executive Dashboard | B26: DateFormat | C26: M/D/YYYY | E26: NaN | F26: No | G26: Yes | H26: qvapp_variablelist | I26: ac75b553-286a-4091-9aa6-ac9fef2d1202 | J26: qvf-app
A27: Executive Dashboard | B27: TimestampFormat | C27: M/D/YYYY h:mm:ss[.fff] TT | E27: NaN | F27: No | G27: Yes | H27: qvapp_variablelist | I27: 3cafd7e3-8a17-4a71-acdb-dc0a3bee4ee3 | J27: qvf-app
A28: Executive Dashboard | B28: MonthNames | C28: Jan;Feb;Mar;Apr;May;Jun;Jul;Aug;Sep;Oct;Nov;Dec | E28: NaN | F28: No | G28: Yes | H28: qvapp_variablelist | I28: d5467aca-f106-4b10-9ff0-6ac2327f8336 | J28: qvf-app
A29: Executive Dashboard | B29: DayNames | C29: Mon;Tue;Wed;Thu;Fri;Sat;Sun | E29: NaN | F29: No | G29: Yes | H29: qvapp_variablelist | I29: 70e078d5-9a3a-4a94-aa3c-d1753e4fa102 | J29: qvf-app
A30: Executive Dashboard | B30: vCurrentMonthNum | C30: 5 | E30: 5 | F30: No | G30: Yes | H30: qvapp_variablelist | I30: f8d38860-b6dc-4ba4-9bdb-3f026b24b459 | J30: qvf-app
A31: Executive Dashboard | B31: vCurrentMonth | C31: May | E31: 5 | F31: No | G31: Yes | H31: qvapp_variablelist | I31: b29854c2-53e2-47ad-8608-b987a1c55acf | J31: qvf-app
A32: Executive Dashboard | B32: vCurrentYear | C32: 2013 | E32: 2013 | F32: No | G32: Yes | H32: qvapp_variablelist | I32: 3e6785f5-f438-4f7b-b005-989de7a63a19 | J32: qvf-app
A33: Executive Dashboard | B33: vTodaysDate | C33: 41425 | E33: 41425 | F33: No | G33: Yes | H33: qvapp_variablelist | I33: 3f8db8c7-ceda-4958-93fe-ced25544a097 | J33: qvf-app
A34: Executive Dashboard | B34: v12month | C34: 41060 | E34: 41060 | F34: No | G34: Yes | H34: qvapp_variablelist | I34: fabd907b-6a19-4942-9e35-41c1804959ba | J34: qvf-app
A35: Executive Dashboard | B35: vRolling12months | C35: 41060 | E35: 41060 | F35: No | G35: Yes | H35: qvapp_variablelist | I35: 88fda23d-b35e-490e-b6ff-98171e3a7ea6 | J35: qvf-app
A36: Executive Dashboard | B36: vOldDate | C36: 41425 | E36: 41425 | F36: No | G36: Yes | H36: qvapp_variablelist | I36: cf8d6274-feb7-4200-a2fc-855f8ad20015 | J36: qvf-app
A37: Executive Dashboard | B37: vToday | C37: 5/31/2013 | E37: 41425 | F37: No | G37: Yes | H37: qvapp_variablelist | I37: 4f515b4b-09de-4c87-8e6f-13dffc627264 | J37: qvf-app
A38: Executive Dashboard | B38: vAdjDays | C38: 0 | E38: 0 | F38: No | G38: Yes | H38: qvapp_variablelist | I38: b86c7e8a-a66a-42f2-9b60-779b2324c337 | J38: qvf-app
A39: Executive Dashboard | B39: vVolume | C39: 0 | E39: 0 | F39: No | G39: Yes | H39: qvapp_variablelist | I39: eaf3c994-9fc5-4f8e-936d-283ee267c424 | J39: qvf-app
A40: Executive Dashboard | B40: vPrice | C40: 1 | E40: 1 | F40: No | G40: Yes | H40: qvapp_variablelist | I40: 64490398-338b-4c9a-8804-e4881fea735e | J40: qvf-app
A41: Executive Dashboard | B41: vCost | C41: -2 | E41: -2 | F41: No | G41: Yes | H41: qvapp_variablelist | I41: 8ae837ce-5c7c-41dc-9695-779d50787b44 | J41: qvf-app
A42: Executive Dashboard | B42: vShowChart | C42: 1 | E42: 1 | F42: No | G42: Yes | H42: qvapp_variablelist | I42: 1efc7ea9-a4e5-49c3-9eb4-5c6baeabf968 | J42: qvf-app
A43: Executive Dashboard | B43: vTargetSales | C43: =sum([Budget Amount]) | E43: NaN | F43: Yes | G43: Yes | H43: qvapp_variablelist | I43: 17718c1a-9592-424b-84dd-14b579e6cd1d | J43: qvf-app
...

Sheet Bookmarks
C2: Bookmarks · saved selections
A5: =HYPERLINK("#'Discovery'!A1","« Back to Discovery") | B5: Saved selections with title, description and stored selection text.
A6: App | B6: ID | C6: Title | D6: Description | E6: Created | F6: Stored strings (selections)
A7: Executive Dashboard | B7: SmDXrz | F7: JsonProperty | sheetId | "FaQeFa" | JsonProperty> | selectionFields | "Product Sub Group Desc, Sales Rep Name" | JsonProperty | creationDate | "2014-08-14" | qInfo | SmDXrz | bookmark | qMetaDef | JsonProperty/ | title | "Sales Analysis - Low Margin Sales" | JsonProperty | description | Product Sub Group Desc | Wine | Preserves | Sugar | Coffee | Cheese | Deli Meats | Hot Dogs | Bologna | Fresh Vegetables | Fresh Fruit | Sales Rep Name | Amalia Craig | Brenda Kegler | Cart Lynch | Cary Frank | Deborah Halmon | Dennis Fisher | Judy Rowlett | Cheryle Sincock | Don Simmons | Jimmie Holley
A8: Executive Dashboard | B8: gG01 | F8: JsonProperty* | title | "Sales vs Margin by Sales Rep" | JsonProperty | description | JsonProperty | sheetId | "FaQeFa" | JsonProperty | creationDate | "2014-02-13" | JsonObject | qMeta | JsonObject | qSelectionInfo | HyperCube | qHyperCube | JsonProperty | title | "Sales Rep Name" | JsonProperty | autoSort | true | JsonProperty | cId | "qvHTMd" | JsonProperty | othersLabel | "Others" | Sales Rep Name | Sales Rep Name | $ascii | $text | JsonProperty | autoSort | true | JsonProperty | cId | "RPfsxLb" | Margin %
A9: Executive Dashboard | B9: QTzpe | F9: JsonProperty# | title | "Average Sales Per Day" | JsonProperty | description | JsonProperty | sheetId | "FaQeFa" | JsonProperty | creationDate | "2014-02-13" | JsonObject | qMeta | JsonObject | qSelectionInfo | HyperCube | qHyperCube | JsonProperty | title | "Year Month" | JsonProperty | autoSort | true | JsonProperty | cId | "EtdNTQp" | JsonProperty | othersLabel | "Others" Year Month | Year Month | $key | $numeric | $integer $timestamp | $date | JsonProperty | autoSort | true | JsonProperty | cId | "SwcJjj"
A10: Executive Dashboard | B10: PqgqBSe | F10: JsonProperty: | title | "Total Revenue by Product Group = $18,226,161" | JsonProperty | description | JsonProperty | sheetId | "FaQeFa" | JsonProperty | creationDate | "2014-02-13" | JsonObject | qMeta | JsonObject | qSelectionInfo | HyperCube | qHyperCube | JsonProperty$ | title | "Product Sub Group Desc" | JsonProperty | autoSort | true | JsonProperty | cId | "HBLVQ" | JsonProperty | othersLabel | "Others" | Product Sub Group Desc | Product Sub Group Desc | $ascii | $text | JsonProperty | autoSort | true | JsonProperty | cId | "GCkjvhs" | Revenue
